11m         Normal    NotTriggerScaleUp              pod/mongodb-d948b8585-wnvx7             pod didn't trigger scale-up:
11m         Normal    NotTriggerScaleUp              pod/dispatch-service-5589cf949c-mxbp6   pod didn't trigger scale-up:
11m         Normal    NotTriggerScaleUp              pod/dispatch-service-5589cf949c-rqx6w   pod didn't trigger scale-up:
10m         Normal    TriggeredScaleUp               pod/mongodb-d948b8585-wnvx7             pod triggered scale-up: [{NODE_REDACTED 1->3 (max: 10)}]
10m         Normal    TriggeredScaleUp               pod/dispatch-service-5589cf949c-mxbp6   pod triggered scale-up: [{NODE_REDACTED 1->3 (max: 10)}]
10m         Normal    TriggeredScaleUp               pod/dispatch-service-5589cf949c-rqx6w   pod triggered scale-up: [{NODE_REDACTED 1->3 (max: 10)}]
10m         Warning   FailedScheduling               pod/mongodb-d948b8585-wnvx7             0/1 nodes are available: 1 node(s) had untolerated taint(s). no new claims to deallocate, preemption: 0/1 nodes are available: 1 Preemption is not helpful for scheduling.
10m         Warning   FailedScheduling               pod/dispatch-service-5589cf949c-mxbp6   0/1 nodes are available: 1 node(s) had untolerated taint(s). no new claims to deallocate, preemption: 0/1 nodes are available: 1 Preemption is not helpful for scheduling.
10m         Warning   FailedScheduling               pod/dispatch-service-5589cf949c-rqx6w   0/1 nodes are available: 1 node(s) had untolerated taint(s). no new claims to deallocate, preemption: 0/1 nodes are available: 1 Preemption is not helpful for scheduling.
10m         Warning   FailedScheduling               pod/mongodb-d948b8585-wnvx7             0/2 nodes are available: 1 Insufficient cpu, 1 Too many pods, 1 node(s) had untolerated taint(s). no new claims to deallocate, preemption: 0/2 nodes are available: 1 No preemption victims found for incoming pod, 1 Preemption is not helpful for scheduling.
9m52s       Normal    Scheduled                      pod/mongodb-d948b8585-wnvx7             Successfully assigned energy/mongodb-d948b8585-wnvx7 to NODE_REDACTED
9m43s       Normal    SuccessfulAttachVolume         pod/mongodb-d948b8585-wnvx7             AttachVolume.Attach succeeded for volume "pvc-6eb214d1-f9ea-4805-bc26-d0e417e907c3"
9m38s       Normal    Pulling                        pod/mongodb-d948b8585-wnvx7             Pulling image "mongo:4.4"
9m37s       Warning   FailedScheduling               pod/dispatch-service-5589cf949c-rqx6w   0/2 nodes are available: 1 Insufficient cpu, 1 Too many pods, 1 node(s) had untolerated taint(s). no new claims to deallocate, preemption: 0/2 nodes are available: 1 No preemption victims found for incoming pod, 1 Preemption is not helpful for scheduling.
9m37s       Warning   FailedScheduling               pod/dispatch-service-5589cf949c-mxbp6   0/2 nodes are available: 1 Insufficient cpu, 1 Too many pods, 1 node(s) had untolerated taint(s). no new claims to deallocate, preemption: 0/2 nodes are available: 1 No preemption victims found for incoming pod, 1 Preemption is not helpful for scheduling.
9m20s       Normal    Created                        pod/mongodb-d948b8585-wnvx7             Created container: mongodb
9m20s       Normal    Pulled                         pod/mongodb-d948b8585-wnvx7             Successfully pulled image "mongo:4.4" in 18.096s (18.096s including waiting). Image size: 166163173 bytes.
9m19s       Normal    Started                        pod/mongodb-d948b8585-wnvx7             Started container mongodb
9m17s       Warning   FailedScheduling               pod/dispatch-service-5589cf949c-mxbp6   0/3 nodes are available: 1 Insufficient cpu, 1 Too many pods, 2 node(s) had untolerated taint(s). no new claims to deallocate, preemption: 0/3 nodes are available: 1 No preemption victims found for incoming pod, 2 Preemption is not helpful for scheduling.
9m17s       Warning   FailedScheduling               pod/dispatch-service-5589cf949c-rqx6w   0/3 nodes are available: 1 Insufficient cpu, 1 Too many pods, 2 node(s) had untolerated taint(s). no new claims to deallocate, preemption: 0/3 nodes are available: 1 No preemption victims found for incoming pod, 2 Preemption is not helpful for scheduling.
9m1s        Warning   FailedScheduling               pod/dispatch-service-5589cf949c-rqx6w   0/4 nodes are available: 1 Insufficient cpu, 1 Too many pods, 3 node(s) had untolerated taint(s). no new claims to deallocate, preemption: 0/4 nodes are available: 1 No preemption victims found for incoming pod, 3 Preemption is not helpful for scheduling.
9m1s        Warning   FailedScheduling               pod/dispatch-service-5589cf949c-mxbp6   0/4 nodes are available: 1 Insufficient cpu, 1 Too many pods, 3 node(s) had untolerated taint(s). no new claims to deallocate, preemption: 0/4 nodes are available: 1 No preemption victims found for incoming pod, 3 Preemption is not helpful for scheduling.
8m34s       Warning   FailedScheduling               pod/dispatch-service-5589cf949c-mxbp6   0/4 nodes are available: 1 Too many pods, 2 Insufficient cpu, 2 node(s) had untolerated taint(s). no new claims to deallocate, preemption: 0/4 nodes are available: 2 No preemption victims found for incoming pod, 2 Preemption is not helpful for scheduling.
8m34s       Warning   FailedScheduling               pod/dispatch-service-5589cf949c-rqx6w   0/4 nodes are available: 1 Too many pods, 2 Insufficient cpu, 2 node(s) had untolerated taint(s). no new claims to deallocate, preemption: 0/4 nodes are available: 2 No preemption victims found for incoming pod, 2 Preemption is not helpful for scheduling.
8m25s       Normal    Scheduled                      pod/dispatch-service-5589cf949c-rqx6w   Successfully assigned energy/dispatch-service-5589cf949c-rqx6w to NODE_REDACTED
8m25s       Normal    Scheduled                      pod/dispatch-service-5589cf949c-mxbp6   Successfully assigned energy/dispatch-service-5589cf949c-mxbp6 to NODE_REDACTED
8m4s        Normal    Pulling                        pod/dispatch-service-5589cf949c-rqx6w   Pulling image "ghcr.io/azure-samples/aks-store-demo/makeline-service:latest"
8m4s        Normal    Pulling                        pod/dispatch-service-5589cf949c-mxbp6   Pulling image "ghcr.io/azure-samples/aks-store-demo/makeline-service:latest"
7m53s       Normal    Created                        pod/dispatch-service-5589cf949c-rqx6w   Created container: dispatch-service
7m53s       Normal    Created                        pod/dispatch-service-5589cf949c-mxbp6   Created container: dispatch-service
7m53s       Normal    Pulled                         pod/dispatch-service-5589cf949c-rqx6w   Successfully pulled image "ghcr.io/azure-samples/aks-store-demo/makeline-service:latest" in 11.266s (11.266s including waiting). Image size: 14820165 bytes.
7m53s       Normal    Pulled                         pod/dispatch-service-5589cf949c-mxbp6   Successfully pulled image "ghcr.io/azure-samples/aks-store-demo/makeline-service:latest" in 11.651s (11.651s including waiting). Image size: 14820165 bytes.
7m52s       Normal    Started                        pod/dispatch-service-5589cf949c-mxbp6   Started container dispatch-service
7m52s       Normal    Started                        pod/dispatch-service-5589cf949c-rqx6w   Started container dispatch-service
1s          Normal    Killing                        pod/mongodb-d948b8585-wnvx7             Stopping container mongodb
1s          Normal    SuccessfulDelete               replicaset/mongodb-d948b8585            Deleted pod: mongodb-d948b8585-wnvx7
1s          Normal    ScalingReplicaSet              deployment/mongodb                      Scaled down replica set mongodb-d948b8585 from 1 to 0
0s          Normal    ScalingReplicaSet              deployment/mongodb                      Scaled up replica set mongodb-d948b8585 from 0 to 1
0s          Normal    Scheduled                      pod/mongodb-d948b8585-ptjjt             Successfully assigned energy/mongodb-d948b8585-ptjjt to NODE_REDACTED
0s          Normal    SuccessfulCreate               replicaset/mongodb-d948b8585            Created pod: mongodb-d948b8585-ptjjt
